Failure # 1 (occurred at 2021-09-23_18-11-20)
Traceback (most recent call last):
  File "/Users/lorneez/opt/anaconda3/lib/python3.8/site-packages/ray/tune/trial_runner.py", line 739, in _process_trial
    results = self.trial_executor.fetch_result(trial)
  File "/Users/lorneez/opt/anaconda3/lib/python3.8/site-packages/ray/tune/ray_trial_executor.py", line 729, in fetch_result
    result = ray.get(trial_future[0], timeout=DEFAULT_GET_TIMEOUT)
  File "/Users/lorneez/opt/anaconda3/lib/python3.8/site-packages/ray/_private/client_mode_hook.py", line 82, in wrapper
    return func(*args, **kwargs)
  File "/Users/lorneez/opt/anaconda3/lib/python3.8/site-packages/ray/worker.py", line 1564, in get
    raise value.as_instanceof_cause()
ray.exceptions.RayTaskError(CannotListenError): [36mray::RLlibTrainer.train()[39m (pid=91550, ip=10.194.133.147)
  File "python/ray/_raylet.pyx", line 534, in ray._raylet.execute_task
  File "python/ray/_raylet.pyx", line 484, in ray._raylet.execute_task.function_executor
  File "/Users/lorneez/opt/anaconda3/lib/python3.8/site-packages/ray/_private/function_manager.py", line 563, in actor_method_executor
    return method(__ray_actor, *args, **kwargs)
  File "/Users/lorneez/Projects/390/project_Playground/projekt/rllib_wrapper.py", line 543, in train
    stats = super().train()
  File "/Users/lorneez/opt/anaconda3/lib/python3.8/site-packages/ray/rllib/agents/trainer.py", line 640, in train
    raise e
  File "/Users/lorneez/opt/anaconda3/lib/python3.8/site-packages/ray/rllib/agents/trainer.py", line 629, in train
    result = Trainable.train(self)
  File "/Users/lorneez/opt/anaconda3/lib/python3.8/site-packages/ray/tune/trainable.py", line 237, in train
    result = self.step()
  File "/Users/lorneez/opt/anaconda3/lib/python3.8/site-packages/ray/rllib/agents/trainer_template.py", line 183, in step
    res = next(self.train_exec_impl)
  File "/Users/lorneez/opt/anaconda3/lib/python3.8/site-packages/ray/util/iter.py", line 756, in __next__
    return next(self.built_iterator)
  File "/Users/lorneez/opt/anaconda3/lib/python3.8/site-packages/ray/util/iter.py", line 783, in apply_foreach
    for item in it:
  File "/Users/lorneez/opt/anaconda3/lib/python3.8/site-packages/ray/util/iter.py", line 783, in apply_foreach
    for item in it:
  File "/Users/lorneez/opt/anaconda3/lib/python3.8/site-packages/ray/util/iter.py", line 843, in apply_filter
    for item in it:
  File "/Users/lorneez/opt/anaconda3/lib/python3.8/site-packages/ray/util/iter.py", line 843, in apply_filter
    for item in it:
  File "/Users/lorneez/opt/anaconda3/lib/python3.8/site-packages/ray/util/iter.py", line 783, in apply_foreach
    for item in it:
  File "/Users/lorneez/opt/anaconda3/lib/python3.8/site-packages/ray/util/iter.py", line 783, in apply_foreach
    for item in it:
  File "/Users/lorneez/opt/anaconda3/lib/python3.8/site-packages/ray/util/iter.py", line 783, in apply_foreach
    for item in it:
  [Previous line repeated 1 more time]
  File "/Users/lorneez/opt/anaconda3/lib/python3.8/site-packages/ray/util/iter.py", line 876, in apply_flatten
    for item in it:
  File "/Users/lorneez/opt/anaconda3/lib/python3.8/site-packages/ray/util/iter.py", line 828, in add_wait_hooks
    item = next(it)
  File "/Users/lorneez/opt/anaconda3/lib/python3.8/site-packages/ray/util/iter.py", line 783, in apply_foreach
    for item in it:
  File "/Users/lorneez/opt/anaconda3/lib/python3.8/site-packages/ray/util/iter.py", line 783, in apply_foreach
    for item in it:
  File "/Users/lorneez/opt/anaconda3/lib/python3.8/site-packages/ray/util/iter.py", line 783, in apply_foreach
    for item in it:
  [Previous line repeated 1 more time]
  File "/Users/lorneez/opt/anaconda3/lib/python3.8/site-packages/ray/util/iter.py", line 471, in base_iterator
    yield ray.get(futures, timeout=timeout)
  File "/Users/lorneez/opt/anaconda3/lib/python3.8/site-packages/ray/_private/client_mode_hook.py", line 82, in wrapper
    return func(*args, **kwargs)
ray.exceptions.RayTaskError(CannotListenError): [36mray::RolloutWorker.par_iter_next()[39m (pid=91549, ip=10.194.133.147)
OSError: [Errno 48] Address already in use

During handling of the above exception, another exception occurred:

[36mray::RolloutWorker.par_iter_next()[39m (pid=91549, ip=10.194.133.147)
  File "python/ray/_raylet.pyx", line 523, in ray._raylet.execute_task
  File "python/ray/_raylet.pyx", line 530, in ray._raylet.execute_task
  File "python/ray/_raylet.pyx", line 534, in ray._raylet.execute_task
  File "python/ray/_raylet.pyx", line 484, in ray._raylet.execute_task.function_executor
  File "/Users/lorneez/opt/anaconda3/lib/python3.8/site-packages/ray/_private/function_manager.py", line 563, in actor_method_executor
    return method(__ray_actor, *args, **kwargs)
  File "/Users/lorneez/opt/anaconda3/lib/python3.8/site-packages/ray/util/iter.py", line 1151, in par_iter_next
    return next(self.local_it)
  File "/Users/lorneez/opt/anaconda3/lib/python3.8/site-packages/ray/rllib/evaluation/rollout_worker.py", line 339, in gen_rollouts
    yield self.sample()
  File "/Users/lorneez/opt/anaconda3/lib/python3.8/site-packages/ray/rllib/evaluation/rollout_worker.py", line 740, in sample
    batches = [self.input_reader.next()]
  File "/Users/lorneez/opt/anaconda3/lib/python3.8/site-packages/ray/rllib/evaluation/sampler.py", line 101, in next
    batches = [self.get_data()]
  File "/Users/lorneez/opt/anaconda3/lib/python3.8/site-packages/ray/rllib/evaluation/sampler.py", line 231, in get_data
    item = next(self.rollout_provider)
  File "/Users/lorneez/opt/anaconda3/lib/python3.8/site-packages/ray/rllib/evaluation/sampler.py", line 660, in _env_runner
    rendered = base_env.try_render()
  File "/Users/lorneez/opt/anaconda3/lib/python3.8/site-packages/ray/rllib/env/base_env.py", line 455, in try_render
    return self.envs[env_id].render()
  File "/Users/lorneez/Projects/390/project_Playground/neural_mmo/forge/trinity/env.py", line 369, in render
    self.client = Application(self)
  File "/Users/lorneez/Projects/390/project_Playground/neural_mmo/forge/trinity/twistedserver.py", line 145, in __init__
    reactor.listenTCP(port, site)
  File "/Users/lorneez/opt/anaconda3/lib/python3.8/site-packages/twisted/internet/posixbase.py", line 495, in listenTCP
    p.startListening()
  File "/Users/lorneez/opt/anaconda3/lib/python3.8/site-packages/twisted/internet/tcp.py", line 1363, in startListening
    raise CannotListenError(self.interface, self.port, le)
twisted.internet.error.CannotListenError: Couldn't listen on any:8080: [Errno 48] Address already in use.

